Workbook

Sheet 说明与汇总
A1: Mango Mock UI 全元素与 mangoautomation 操作覆盖测试设计
A3: 目标：以新版 data-testid 为唯一稳定定位入口，逐一覆盖所有交互控件，并验证 mangoautomation 同步 Web 层公开的 103 种操作/断言方法。该工作簿是测试设计，不代表已启动浏览器执行。
A6: 元素ID总数 | C6: 交互控件总数 | E6: 操作目录总数 | G6: mangoautomation已支持
A7: =COUNTA('全元素清单'!$B$2:$B$301) | C7: =COUNTA('交互元素逐一操作'!$D$2:$D$201) | E7: =COUNTA('操作方法覆盖'!$E$2:$E$151) | G7: =COUNTIF('操作方法覆盖'!$Q$2:$Q$151,"已支持")
A10: 执行基址 | B10: ${base_url}/
A11: 定位规范 | B11: 统一使用 [data-testid="元素ID"]，禁止依赖动态 class 或文本作为主定位器
A12: 测试隔离 | B12: 业务/UI 协议用例先创建 test_run，注入 X-Test-Run-ID 与 X-Tenant-ID
A13: 运行时 | B13: WebDriverFactory.create_sync_runtime + BaseData.bind_web + SyncWebDevice
A14: 点击范围 | B14: 130 个交互控件逐一操作；禁用控件只做禁用断言，其余只读元素进入全元素清单
A15: 执行建议 | B15: 按页面和序号串行执行；弹窗、页签、上传下载、权限操作单独分组
A16: HTML来源 | B16: /Users/mango/code/mango-mock/app/web/static/index.html
A17: 操作来源 | B17: /Users/mango/code/mango-mock/app/web/static/js/components.js
A20: 执行顺序 | B20: 1. 创建运行并登录 | C20: 2. 基础元素操作 | D20: 3. 表单/上传下载 | E20: 4. 弹窗/页签 | F20: 5. 断言 | G20: 6. 协议交互 | H20: 7. 清理运行
A21: 失败处理 | B21: 记录截图 | C21: 保存 operation-event-log | D21: 保存元素ID | E21: 保存方法和参数 | F21: 保留 trace_id | G21: 标记阻塞 | H21: 继续安全用例
A22: 禁止 | B22: 不使用旧元素ID | C22: 不硬编码动态class | D22: 不跨 test_run 复用Token | E22: 不并行操作同一页面 | F22: 不吞异常 | G22: 不跳过清理 | H22: 不直接改远端数据
A23: 状态 | B23: 待执行 | C23: 执行中 | D23: 通过 | E23: 失败 | F23: 阻塞 | G23: 不适用 | H23: 需人工确认

Sheet 操作方法覆盖
A1: 序号 | B1: 用例ID | C1: 分组 | D1: 自动化类型 | E1: 方法 | F1: 方法说明 | G1: 目标元素ID | H1: 定位方式 | I1: 定位表达式 | J1: 参数签名 | K1: 操作参数(JSON) | L1: 前置条件 | M1: 预期结果 | N1: 验证元素ID | O1: 优先级 | P1: 执行状态 | Q1: 支持状态 | R1: 源码位置 | S1: 备注
A2: 1 | B2: UI-OP-001 | C2: 元素操作 | D2: 操作 | E2: w_click | F2: 元素单击 | G2: single-click-target | H2: TEST_ID | I2: [data-testid="single-click-target"] | J2: locating | K2: {} | L2: 打开首页；点击 nav-components；等待 components-page 可见 | M2: 元素单击执行成功，operation-event-log/关联状态元素发生预期变化 | N2: operation-event-log | O2: P0 | P2: 待执行 | Q2: 已支持 | R2: _element.py:62
A3: 2 | B3: UI-OP-002 | C3: 元素操作 | D3: 操作 | E3: w_dblclick | F3: 元素双击 | G3: double-click-target | H3: TEST_ID | I3: [data-testid="double-click-target"] | J3: locating | K3: {} | L3: 打开首页；点击 nav-components；等待 components-page 可见 | M3: 元素双击执行成功，operation-event-log/关联状态元素发生预期变化 | N3: operation-event-log | O3: P2 | P3: 待执行 | Q3: 已支持 | R3: _element.py:67
A4: 3 | B4: UI-OP-003 | C4: 元素操作 | D4: 操作 | E4: w_force_click | F4: 强制单击 | G4: force-click-target | H4: TEST_ID | I4: [data-testid="force-click-target"] | J4: locating | K4: {} | L4: 打开首页；点击 nav-components；等待 components-page 可见 | M4: 强制单击执行成功，operation-event-log/关联状态元素发生预期变化 | N4: operation-event-log | O4: P2 | P4: 待执行 | Q4: 已支持 | R4: _element.py:72
A5: 4 | B5: UI-OP-004 | C5: 元素操作 | D5: 操作 | E5: w_input | F5: 元素输入 | G5: keyboard-target | H5: TEST_ID | I5: [data-testid="keyboard-target"] | J5: locating, input_value | K5: {"input_value":"AUTO_UI_INPUT"} | L5: 打开首页；点击 nav-components；等待 components-page 可见 | M5: 元素输入执行成功，operation-event-log/关联状态元素发生预期变化 | N5: operation-event-log | O5: P0 | P5: 待执行 | Q5: 已支持 | R5: _element.py:84
A6: 5 | B6: UI-OP-005 | C6: 元素操作 | D6: 操作 | E6: w_hover | F6: 鼠标悬停 | G6: hover-target | H6: TEST_ID | I6: [data-testid="hover-target"] | J6: locating | K6: {} | L6: 打开首页；点击 nav-components；等待 components-page 可见 | M6: 鼠标悬停执行成功，operation-event-log/关联状态元素发生预期变化 | N6: operation-event-log | O6: P2 | P6: 待执行 | Q6: 已支持 | R6: _element.py:89
A7: 6 | B7: UI-OP-006 | C7: 元素操作 | D7: 操作 | E7: w_get_text | F7: 获取元素文本 | G7: read-text-target | H7: TEST_ID | I7: [data-testid="read-text-target"] | J7: locating, set_cache_key | K7: {"set_cache_key":"ui_read_text"} | L7: 打开首页；点击 nav-components；等待 components-page 可见 | M7: 获取元素文本成功，返回值非空并写入指定缓存键 | N7: operation-event-log | O7: P2 | P7: 待执行 | Q7: 已支持 | R7: _element.py:97
A8: 7 | B8: UI-OP-007 | C8: 元素操作 | D8: 操作 | E8: w_clear_input | F8: 元素清空再输入 | G8: keyboard-target | H8: TEST_ID | I8: [data-testid="keyboard-target"] | J8: locating, input_value | K8: {"input_value":"AUTO_UI_RESET"} | L8: 打开首页；点击 nav-components；等待 components-page 可见 | M8: 元素清空再输入执行成功，operation-event-log/关联状态元素发生预期变化 | N8: operation-event-log | O8: P2 | P8: 待执行 | Q8: 已支持 | R8: _element.py:126
A9: 8 | B9: UI-OP-008 | C9: 元素操作 | D9: 操作 | E9: w_many_click | F9: 多元素循环单击 | G9: many-click-targets | H9: TEST_ID | I9: [data-testid="many-click-targets"] | J9: locating | K9: {} | L9: 打开首页；点击 nav-components；等待 components-page 可见 | M9: 多元素循环单击执行成功，operation-event-log/关联状态元素发生预期变化 | N9: operation-event-log | O9: P2 | P9: 待执行 | Q9: 已支持 | R9: _element.py:132
A10: 9 | B10: UI-OP-009 | C10: 元素操作 | D10: 操作 | E10: w_upload_files | F10: 上传文件 | G10: ui-file-input | H10: TEST_ID | I10: [data-testid="ui-file-input"] | J10: locating, file_path | K10: {"file_path":"${project_root}/auto_tests/ui/simple_ui/data/upload.txt"} | L10: 打开首页；点击 nav-components；等待 components-page 可见 | M10: 文件选择成功，页面显示上传文件信息且无业务错误 | N10: operation-event-log | O10: P0 | P10: 待执行 | Q10: 已支持 | R10: _element.py:143
A11: 10 | B11: UI-OP-010 | C11: 元素操作 | D11: 操作 | E11: w_download | F11: 下载文件 | G11: download-file | H11: TEST_ID | I11: [data-testid="download-file"] | J11: locating, file_key | K11: {"file_key":"ui_download_path"} | L11: 打开首页；点击 nav-components；等待 components-page 可见 | M11: 触发下载，文件存在且下载路径写入缓存 | N11: operation-event-log | O11: P1 | P11: 待执行 | Q11: 已支持 | R11: _element.py:207
A12: 11 | B12: UI-OP-011 | C12: 元素操作 | D12: 操作 | E12: w_scroll_to_element | F12: 滚动到元素位置 | G12: assert-out-of-viewport | H12: TEST_ID | I12: [data-testid="assert-out-of-viewport"] | J12: locating | K12: {} | L12: 打开首页；点击 nav-components；等待 components-page 可见；保持目标位于滚动容器视窗外 | M12: 滚动到元素位置执行成功，operation-event-log/关联状态元素发生预期变化 | N12: scroll-event-status | O12: P2 | P12: 待执行 | Q12: 已支持 | R12: _element.py:219
A13: 12 | B13: UI-OP-012 | C13: 元素操作 | D13: 操作 | E13: w_right_click | F13: 元素右键点击 | G13: right-click-target | H13: TEST_ID | I13: [data-testid="right-click-target"] | J13: locating | K13: {} | L13: 打开首页；点击 nav-components；等待 components-page 可见 | M13: 元素右键点击执行成功，operation-event-log/关联状态元素发生预期变化 | N13: operation-event-log | O13: P2 | P13: 待执行 | Q13: 已支持 | R13: _element.py:224
... A19: 18 | B19: UI-OP-018 | C19: 元素操作 | D19: 操作 | E19: w_ele_screenshot | F19: 元素截图 | G19: read-text-target | H19: TEST_ID | I19: [data-testid="read-text-target"] | J19: locating, path | K19: {"path":"${screenshot_dir}/read-text-target.png"} | L19: 打开首页；点击 nav-components；等待 components-page 可见 | M19: 元素截图执行成功，operation-event-log/关联状态元素发生预期变化 | N19: operation-event-log | O19: P2 | P19: 待执行 | Q19: 已支持 | R19: _element.py:317
A20: 19 | B20: UI-OP-019 | C20: 元素操作 | D20: 操作 | E20: w_drag_to | F20: 拖动A元素到达B | G20: drag-source | H20: TEST_ID | I20: [data-testid="drag-source"] | J20: locating1, locating2 | K20: {"target_element_id":"drop-target"} | L20: 打开首页；点击 nav-components；等待 components-page 可见；目标元素为 drop-target | M20: 拖动动作完成，operation-event-log 或 drop-target 状态更新 | N20: pointer-event-status | O20: P1 | P20: 待执行 | Q20: 已支持 | R20: _element.py:324 | S20: 执行器需把 target_element_id 解析为第二个 Locator
A21: 20 | B21: UI-OP-020 | C21: 元素操作 | D21: 操作 | E21: w_clear | F21: 清空输入框 | G21: keyboard-target | H21: TEST_ID | I21: [data-testid="keyboard-target"] | J21: locating | K21: {} | L21: 打开首页；点击 nav-components；等待 components-page 可见 | M21: 清空输入框执行成功，operation-event-log/关联状态元素发生预期变化 | N21: operation-event-log | O21: P2 | P21: 待执行 | Q21: 已支持 | R21: _element.py:329
A22: 21 | B22: UI-OP-021 | C22: 元素操作 | D22: 操作 | E22: w_type | F22: 逐字输入 | G22: keyboard-target | H22: TEST_ID | I22: [data-testid="keyboard-target"] | J22: locating, text | K22: {"text":"AUTO_TYPE"} | L22: 打开首页；点击 nav-components；等待 components-page 可见 | M22: 逐字输入执行成功，operation-event-log/关联状态元素发生预期变化 | N22: operation-event-log | O22: P2 | P22: 待执行 | Q22: 已支持 | R22: _element.py:336
A23: 22 | B23: UI-OP-022 | C23: 元素操作 | D23: 操作 | E23: w_press_sequentially | F23: 逐字输入并触发键盘事件 | G23: keyboard-target | H23: TEST_ID | I23: [data-testid="keyboard-target"] | J23: locating, text | K23: {"text":"AUTO_KEYS"} | L23: 打开首页；点击 nav-components；等待 components-page 可见 | M23: 逐字输入并触发键盘事件执行成功，operation-event-log/关联状态元素发生预期变化 | N23: operation-event-log | O23: P2 | P23: 待执行 | Q23: 已支持 | R23: _element.py:343
A24: 23 | B24: UI-OP-023 | C24: 元素操作 | D24: 操作 | E24: w_press | F24: 元素按键 | G24: keyboard-target | H24: TEST_ID | I24: [data-testid="keyboard-target"] | J24: locating, key | K24: {"key":"Control+A"} | L24: 打开首页；点击 nav-components；等待 components-page 可见 | M24: 元素按键执行成功，operation-event-log/关联状态元素发生预期变化 | N24: operation-event-log | O24: P2 | P24: 待执行 | Q24: 已支持 | R24: _element.py:350
A25: 24 | B25: UI-OP-024 | C25: 元素操作 | D25: 操作 | E25: w_focus | F25: 元素聚焦 | G25: keyboard-target | H25: TEST_ID | I25: [data-testid="keyboard-target"] | J25: locating | K25: {} | L25: 打开首页；点击 nav-components；等待 components-page 可见 | M25: 元素聚焦执行成功，operation-event-log/关联状态元素发生预期变化 | N25: operation-event-log | O25: P2 | P25: 待执行 | Q25: 已支持 | R25: _element.py:355
A26: 25 | B26: UI-OP-025 | C26: 元素操作 | D26: 操作 | E26: w_blur | F26: 元素失焦 | G26: keyboard-target | H26: TEST_ID | I26: [data-testid="keyboard-target"] | J26: locating | K26: {} | L26: 打开首页；点击 nav-components；等待 components-page 可见 | M26: 元素失焦执行成功，operation-event-log/关联状态元素发生预期变化 | N26: operation-event-log | O26: P2 | P26: 待执行 | Q26: 已支持 | R26: _element.py:360
A27: 26 | B27: UI-OP-026 | C27: 元素操作 | D27: 操作 | E27: w_check | F27: 勾选复选框或单选框 | G27: capability-assertion | H27: TEST_ID | I27: [data-testid="capability-assertion"] | J27: locating | K27: {} | L27: 打开首页；点击 nav-components；等待 components-page 可见 | M27: 勾选复选框或单选框执行成功，operation-event-log/关联状态元素发生预期变化 | N27: operation-event-log | O27: P0 | P27: 待执行 | Q27: 已支持 | R27: _element.py:365
A28: 27 | B28: UI-OP-027 | C28: 元素操作 | D28: 操作 | E28: w_uncheck | F28: 取消勾选复选框 | G28: capability-assertion | H28: TEST_ID | I28: [data-testid="capability-assertion"] | J28: locating | K28: {} | L28: 打开首页；点击 nav-components；等待 components-page 可见 | M28: 取消勾选复选框执行成功，operation-event-log/关联状态元素发生预期变化 | N28: operation-event-log | O28: P2 | P28: 待执行 | Q28: 已支持 | R28: _element.py:370
A29: 28 | B29: UI-OP-028 | C29: 元素操作 | D29: 操作 | E29: w_set_checked | F29: 设置选中状态 | G29: capability-assertion | H29: TEST_ID | I29: [data-testid="capability-assertion"] | J29: locating, checked | K29: {"checked":true} | L29: 打开首页；点击 nav-components；等待 components-page 可见 | M29: 设置选中状态执行成功，operation-event-log/关联状态元素发生预期变化 | N29: operation-event-log | O29: P2 | P29: 待执行 | Q29: 已支持 | R29: _element.py:377
A30: 29 | B30: UI-OP-029 | C30: 元素操作 | D30: 操作 | E30: w_select_option | F30: 选择下拉选项 | G30: single-select | H30: TEST_ID | I30: [data-testid="single-select"] | J30: locating, values | K30: {"values":"test"} | L30: 打开首页；点击 nav-components；等待 components-page 可见 | M30: 选择下拉选项执行成功，operation-event-log/关联状态元素发生预期变化 | N30: operation-event-log | O30: P0 | P30: 待执行 | Q30: 已支持 | R30: _element.py:384
A31: 30 | B31: UI-OP-030 | C31: 元素操作 | D31: 操作 | E31: w_select_text | F31: 选中文本 | G31: read-text-target | H31: TEST_ID | I31: [data-testid="read-text-target"] | J31: locating | K31: {} | L31: 打开首页；点击 nav-components；等待 components-page 可见 | M31: 选中文本执行成功，operation-event-log/关联状态元素发生预期变化 | N31: operation-event-log | O31: P2 | P31: 待执行 | Q31: 已支持 | R31: _element.py:389
A32: 31 | B32: UI-OP-031 | C32: 元素操作 | D32: 操作 | E32: w_tap | F32: 触摸点击 | G32: tap-target | H32: TEST_ID | I32: [data-testid="tap-target"] | J32: locating | K32: {} | L32: 打开首页；点击 nav-components；等待 components-page 可见 | M32: 触摸点击执行成功，operation-event-log/关联状态元素发生预期变化 | N32: operation-event-log | O32: P2 | P32: 待执行 | Q32: 已支持 | R32: _element.py:394
... A42: 41 | B42: UI-OP-041 | C42: 浏览器操作 | D42: 操作 | E42: w_screenshot | F42: 整个页面截图 | G42: components-page | H42: TEST_ID | I42: [data-testid="components-page"] | J42: path | K42: {"path":"${screenshot_dir}/mango-mock-page.png"} | L42: 打开首页；点击 nav-components；等待 components-page 可见 | M42: 整个页面截图执行成功，operation-event-log/关联状态元素发生预期变化 | N42: operation-event-log | O42: P2 | P42: 待执行 | Q42: 已支持 | R42: _browser.py:85
A43: 42 | B43: UI-OP-042 | C43: 浏览器操作 | D43: 操作 | E43: w_accept_dialog | F43: 自动接受弹窗 | G43: native-confirm | H43: TEST_ID | I43: [data-testid="native-confirm"] | K43: {} | L43: 打开首页；点击 nav-components；等待 components-page 可见；先点击 native-confirm 并注册接受弹窗处理 | M43: 原生弹窗被预期接受或取消，native-dialog-result 更新 | N43: native-dialog-result | O43: P1 | P43: 待执行 | Q43: 已支持 | R43: _browser.py:111
A44: 43 | B44: UI-OP-043 | C44: 浏览器操作 | D44: 操作 | E44: w_dismiss_dialog | F44: 自动取消弹窗 | G44: native-confirm | H44: TEST_ID | I44: [data-testid="native-confirm"] | K44: {} | L44: 打开首页；点击 nav-components；等待 components-page 可见；先点击 native-confirm 并注册取消弹窗处理 | M44: 原生弹窗被预期接受或取消，native-dialog-result 更新 | N44: native-dialog-result | O44: P1 | P44: 待执行 | Q44: 已支持 | R44: _browser.py:116
A45: 44 | B45: UI-OP-044 | C45: 浏览器操作 | D45: 操作 | E45: w_get_cookie | F45: 获取cookie | G45: browser-storage-result | H45: TEST_ID | I45: [data-testid="browser-storage-result"] | K45: {} | L45: 打开首页；点击 nav-components；等待 components-page 可见 | M45: 获取cookie成功，返回值非空并写入指定缓存键 | N45: operation-event-log | O45: P2 | P45: 待执行 | Q45: 已支持 | R45: _browser.py:121
A46: 45 | B46: UI-OP-045 | C46: 浏览器操作 | D46: 操作 | E46: w_set_cookie | F46: 设置cookie | G46: seed-browser-storage | H46: TEST_ID | I46: [data-testid="seed-browser-storage"] | J46: storage_state | K46: {"storage_state":{"cookies":[{"name":"ui_case","value":"AUTO","domain":"${base_hostname}","path":"/"}],"origins":[]}} | L46: 打开首页；点击 nav-components；等待 components-page 可见 | M46: 设置cookie执行成功，operation-event-log/关联状态元素发生预期变化 | N46: operation-event-log | O46: P2 | P46: 待执行 | Q46: 已支持 | R46: _browser.py:128
A47: 46 | B47: UI-OP-046 | C47: 浏览器操作 | D47: 操作 | E47: w_clear_cookies | F47: 清除所有cookie | G47: clear-browser-storage | H47: TEST_ID | I47: [data-testid="clear-browser-storage"] | K47: {} | L47: 打开首页；点击 nav-components；等待 components-page 可见 | M47: 清除所有cookie执行成功，operation-event-log/关联状态元素发生预期变化 | N47: operation-event-log | O47: P2 | P47: 待执行 | Q47: 已支持 | R47: _browser.py:147
A48: 47 | B48: UI-OP-047 | C48: 浏览器操作 | D48: 操作 | E48: w_clear_storage | F48: 清除本地与会话存储 | G48: clear-browser-storage | H48: TEST_ID | I48: [data-testid="clear-browser-storage"] | K48: {} | L48: 打开首页；点击 nav-components；等待 components-page 可见 | M48: 清除本地与会话存储执行成功，operation-event-log/关联状态元素发生预期变化 | N48: operation-event-log | O48: P2 | P48: 待执行 | Q48: 已支持 | R48: _browser.py:152
A49: 48 | B49: UI-OP-048 | C49: 浏览器操作 | D49: 操作 | E49: w_wait_for_load_state | F49: 等待页面加载状态 | G49: components-page | H49: TEST_ID | I49: [data-testid="components-page"] | J49: state, timeout | K49: {"state":"domcontentloaded","timeout":30000} | L49: 打开首页；点击 nav-components；等待 components-page 可见 | M49: 等待页面加载状态执行成功，operation-event-log/关联状态元素发生预期变化 | N49: operation-event-log | O49: P2 | P49: 待执行 | Q49: 已支持 | R49: _browser.py:160
A50: 49 | B50: UI-OP-049 | C50: 浏览器操作 | D50: 操作 | E50: w_wait_for_url | F50: 等待URL匹配 | G50: history-result | H50: TEST_ID | I50: [data-testid="history-result"] | J50: url, timeout | K50: {"url":"**","timeout":5000} | L50: 打开首页；点击 nav-components；等待 components-page 可见 | M50: 等待URL匹配执行成功，operation-event-log/关联状态元素发生预期变化 | N50: history-result | O50: P2 | P50: 待执行 | Q50: 已支持 | R50: _browser.py:167
A51: 50 | B51: UI-OP-050 | C51: 浏览器操作 | D51: 操作 | E51: w_wait_for_selector | F51: 等待选择器状态 | G51: assert-attached | H51: TEST_ID | I51: [data-testid="assert-attached"] | J51: selector, state, timeout | K51: {"selector":"[data-testid=\"assert-attached\"]","state":"visible","timeout":5000} | L51: 打开首页；点击 nav-components；等待 components-page 可见 | M51: 等待选择器状态执行成功，operation-event-log/关联状态元素发生预期变化 | N51: operation-event-log | O51: P2 | P51: 待执行 | Q51: 已支持 | R51: _browser.py:175
A52: 51 | B52: UI-OP-051 | C52: 浏览器操作 | D52: 操作 | E52: w_wait_for_function | F52: 等待JS条件成立 | G52: operation-event-log | H52: TEST_ID | I52: [data-testid="operation-event-log"] | J52: expression, timeout | K52: {"expression":"() => document.readyState === 'complete'","timeout":5000} | L52: 打开首页；点击 nav-components；等待 components-page 可见 | M52: 等待JS条件成立执行成功，operation-event-log/关联状态元素发生预期变化 | N52: operation-event-log | O52: P2 | P52: 待执行 | Q52: 已支持 | R52: _browser.py:183
A53: 52 | B53: UI-OP-052 | C53: 浏览器操作 | D53: 操作 | E53: w_set_viewport_size | F53: 设置浏览器视口 | G53: components-page | H53: TEST_ID | I53: [data-testid="components-page"] | J53: width, height | K53: {"width":1440,"height":900} | L53: 打开首页；点击 nav-components；等待 components-page 可见 | M53: 设置浏览器视口执行成功，operation-event-log/关联状态元素发生预期变化 | N53: operation-event-log | O53: P2 | P53: 待执行 | Q53: 已支持 | R53: _browser.py:190
A54: 53 | B54: UI-OP-053 | C54: 浏览器操作 | D54: 操作 | E54: w_set_extra_http_headers | F54: 设置额外请求头 | G54: read-extra-headers | H54: TEST_ID | I54: [data-testid="read-extra-headers"] | J54: headers | K54: {"headers":{"X-Test-Run-ID":"${test_run_id}","X-Tenant-ID":"tenant-a"}} | L54: 打开首页；点击 nav-components；等待 components-page 可见 | M54: 设置额外请求头执行成功，operation-event-log/关联状态元素发生预期变化 | N54: operation-event-log | O54: P2 | P54: 待执行 | Q54: 已支持 | R54: _browser.py:196
...

Sheet 全元素清单
A1: 序号 | B1: 元素ID | C1: 所属页面 | D1: 标签 | E1: input类型 | F1: role | G1: 显示文本/说明 | H1: 定位表达式 | I1: 推荐方法 | J1: 可交互 | K1: 禁用 | L1: 方法目录覆盖 | M1: 测试策略 | N1: 执行状态 | O1: 备注
A2: 1 | B2: skip-to-content | C2: global | D2: a | G2: 跳到主要内容 | H2: [data-testid="skip-to-content"] | I2: w_click | J2: 是 | K2: 否 | L2: =IF(COUNTIF('操作方法覆盖'!$G$2:$G$104,B2)>0,"已覆盖","未直接覆盖") | M2: 进入交互元素逐一操作 | N2: 待执行
A3: 2 | B3: app-header | C3: global | D3: header | G3: Mango Mock 多协议自动化测试靶场 运行： 未创建 用户： 未登录 | H3: [data-testid="app-header"] | I3: w_get_text | J3: 否 | K3: 否 | L3: =IF(COUNTIF('操作方法覆盖'!$G$2:$G$104,B3)>0,"已覆盖","未直接覆盖") | M3: 只读/状态元素：定位、读取文本或作为结果验证元素 | N3: 待执行
A4: 3 | B4: brand-lockup | C4: global | D4: div | G4: Mango Mock 多协议自动化测试靶场 | H4: [data-testid="brand-lockup"] | I4: w_get_text | J4: 否 | K4: 否 | L4: =IF(COUNTIF('操作方法覆盖'!$G$2:$G$104,B4)>0,"已覆盖","未直接覆盖") | M4: 只读/状态元素：定位、读取文本或作为结果验证元素 | N4: 待执行
A5: 4 | B5: runtime-summary | C5: global | D5: div | G5: 运行： 未创建 用户： 未登录 | H5: [data-testid="runtime-summary"] | I5: w_get_text | J5: 否 | K5: 否 | L5: =IF(COUNTIF('操作方法覆盖'!$G$2:$G$104,B5)>0,"已覆盖","未直接覆盖") | M5: 只读/状态元素：定位、读取文本或作为结果验证元素 | N5: 待执行
A6: 5 | B6: current-run-id | C6: global | D6: code | G6: 未创建 | H6: [data-testid="current-run-id"] | I6: w_get_text | J6: 否 | K6: 否 | L6: =IF(COUNTIF('操作方法覆盖'!$G$2:$G$104,B6)>0,"已覆盖","未直接覆盖") | M6: 只读/状态元素：定位、读取文本或作为结果验证元素 | N6: 待执行
A7: 6 | B7: current-user | C7: global | D7: strong | G7: 未登录 | H7: [data-testid="current-user"] | I7: w_get_text | J7: 否 | K7: 否 | L7: =IF(COUNTIF('操作方法覆盖'!$G$2:$G$104,B7)>0,"已覆盖","未直接覆盖") | M7: 只读/状态元素：定位、读取文本或作为结果验证元素 | N7: 待执行
A8: 7 | B8: main-navigation | C8: global | D8: nav | G8: 场景目录 HTTP API SSE WebSocket MCP gRPC UI 自动化 | H8: [data-testid="main-navigation"] | I8: w_get_text | J8: 否 | K8: 否 | L8: =IF(COUNTIF('操作方法覆盖'!$G$2:$G$104,B8)>0,"已覆盖","未直接覆盖") | M8: 只读/状态元素：定位、读取文本或作为结果验证元素 | N8: 待执行
A9: 8 | B9: nav-scenarios | C9: global | D9: button | G9: 场景目录 | H9: [data-testid="nav-scenarios"] | I9: w_click | J9: 是 | K9: 否 | L9: =IF(COUNTIF('操作方法覆盖'!$G$2:$G$104,B9)>0,"已覆盖","未直接覆盖") | M9: 进入交互元素逐一操作 | N9: 待执行
A10: 9 | B10: nav-business | C10: global | D10: button | G10: HTTP API | H10: [data-testid="nav-business"] | I10: w_click | J10: 是 | K10: 否 | L10: =IF(COUNTIF('操作方法覆盖'!$G$2:$G$104,B10)>0,"已覆盖","未直接覆盖") | M10: 进入交互元素逐一操作 | N10: 待执行
A11: 10 | B11: nav-sse | C11: global | D11: button | G11: SSE | H11: [data-testid="nav-sse"] | I11: w_click | J11: 是 | K11: 否 | L11: =IF(COUNTIF('操作方法覆盖'!$G$2:$G$104,B11)>0,"已覆盖","未直接覆盖") | M11: 进入交互元素逐一操作 | N11: 待执行
A12: 11 | B12: nav-websocket | C12: global | D12: button | G12: WebSocket | H12: [data-testid="nav-websocket"] | I12: w_click | J12: 是 | K12: 否 | L12: =IF(COUNTIF('操作方法覆盖'!$G$2:$G$104,B12)>0,"已覆盖","未直接覆盖") | M12: 进入交互元素逐一操作 | N12: 待执行
A13: 12 | B13: nav-mcp | C13: global | D13: button | G13: MCP | H13: [data-testid="nav-mcp"] | I13: w_click | J13: 是 | K13: 否 | L13: =IF(COUNTIF('操作方法覆盖'!$G$2:$G$104,B13)>0,"已覆盖","未直接覆盖") | M13: 进入交互元素逐一操作 | N13: 待执行
... A18: 17 | B18: scenario-protocol | C18: scenariosPage | D18: select | G18: 全部协议 HTTP SSE WebSocket MCP gRPC | H18: [data-testid="scenario-protocol"] | I18: w_select_option | J18: 是 | K18: 否 | L18: =IF(COUNTIF('操作方法覆盖'!$G$2:$G$104,B18)>0,"已覆盖","未直接覆盖") | M18: 进入交互元素逐一操作 | N18: 待执行
A19: 18 | B19: scenario-keyword | C19: scenariosPage | D19: input | H19: [data-testid="scenario-keyword"] | I19: w_input | J19: 是 | K19: 否 | L19: =IF(COUNTIF('操作方法覆盖'!$G$2:$G$104,B19)>0,"已覆盖","未直接覆盖") | M19: 进入交互元素逐一操作 | N19: 待执行
A20: 19 | B20: refresh-scenarios | C20: scenariosPage | D20: button | E20: button | G20: 刷新目录 | H20: [data-testid="refresh-scenarios"] | I20: w_click | J20: 是 | K20: 否 | L20: =IF(COUNTIF('操作方法覆盖'!$G$2:$G$104,B20)>0,"已覆盖","未直接覆盖") | M20: 进入交互元素逐一操作 | N20: 待执行
A21: 20 | B21: scenario-catalog | C21: scenariosPage | D21: section | G21: 正在加载场景目录... | H21: [data-testid="scenario-catalog"] | I21: w_get_text | J21: 否 | K21: 否 | L21: =IF(COUNTIF('操作方法覆盖'!$G$2:$G$104,B21)>0,"已覆盖","未直接覆盖") | M21: 只读/状态元素：定位、读取文本或作为结果验证元素 | N21: 待执行
A22: 21 | B22: scenario-result | C22: scenariosPage | D22: pre | G22: 选择场景后可准备确定性数据或验证执行结果 | H22: [data-testid="scenario-result"] | I22: w_get_text | J22: 否 | K22: 否 | L22: =IF(COUNTIF('操作方法覆盖'!$G$2:$G$104,B22)>0,"已覆盖","未直接覆盖") | M22: 只读/状态元素：定位、读取文本或作为结果验证元素 | N22: 待执行
A23: 22 | B23: business-page | C23: global | D23: section | G23: HTTP API 靶场 创建隔离运行后，直接完成登录、订单、审批和异步审查流程 可直接执行 接入方式 标准 HTTP 接口统一位于 /api/v1 ，完整 OpenAPI 定义可在 Swagger 中查看。 打开 Swagger 准备运行 POST /api/v1/test-runs 获得 test_run_id 登录 | H23: [data-testid="business-page"] | I23: w_get_text | J23: 否 | K23: 否 | L23: =IF(COUNTIF('操作方法覆盖'!$G$2:$G$104,B23)>0,"已覆盖","未直接覆盖") | M23: 只读/状态元素：定位、读取文本或作为结果验证元素 | N23: 待执行
A24: 23 | B24: open-swagger | C24: httpPage | D24: a | G24: 打开 Swagger | H24: [data-testid="open-swagger"] | I24: w_click | J24: 是 | K24: 否 | L24: =IF(COUNTIF('操作方法覆盖'!$G$2:$G$104,B24)>0,"已覆盖","未直接覆盖") | M24: 进入交互元素逐一操作 | N24: 待执行
A25: 24 | B25: http-protocol-reference | C25: httpPage | D25: section | G25: HTTP 请求与响应契约 方法、请求体、成功响应和错误响应可直接用于平台配置。 GET POST PUT PATCH DELETE none json form raw multipart 请求实例 POST /api/v1/orders X-Test-Run-ID: run_xxx Authorization: Be | H25: [data-testid="http-protocol-reference"] | I25: w_get_text | J25: 否 | K25: 否 | L25: =IF(COUNTIF('操作方法覆盖'!$G$2:$G$104,B25)>0,"已覆盖","未直接覆盖") | M25: 只读/状态元素：定位、读取文本或作为结果验证元素 | N25: 待执行
A26: 25 | B26: http-method-types | C26: httpPage | D26: div | G26: GET POST PUT PATCH DELETE none json form raw multipart | H26: [data-testid="http-method-types"] | I26: w_get_text | J26: 否 | K26: 否 | L26: =IF(COUNTIF('操作方法覆盖'!$G$2:$G$104,B26)>0,"已覆盖","未直接覆盖") | M26: 只读/状态元素：定位、读取文本或作为结果验证元素 | N26: 待执行
A27: 26 | B27: http-request-example | C27: httpPage | D27: pre | G27: POST /api/v1/orders X-Test-Run-ID: run_xxx Authorization: Bearer token_xxx Idempotency-Key: ORDER-001 {"items":[{"product_id":1,"quantity":2}]} | H27: [data-testid="http-request-example"] | I27: w_get_text | J27: 否 | K27: 否 | L27: =IF(COUNTIF('操作方法覆盖'!$G$2:$G$104,B27)>0,"已覆盖","未直接覆盖") | M27: 只读/状态元素：定位、读取文本或作为结果验证元素 | N27: 待执行
A28: 27 | B28: http-response-example | C28: httpPage | D28: pre | G28: { "code": 0, "message": "成功", "data": { "id": 1, "order_no": "ORDER-2026-001", "status": "created" }, "trace_id": "..." } | H28: [data-testid="http-response-example"] | I28: w_get_text | J28: 否 | K28: 否 | L28: =IF(COUNTIF('操作方法覆盖'!$G$2:$G$104,B28)>0,"已覆盖","未直接覆盖") | M28: 只读/状态元素：定位、读取文本或作为结果验证元素 | N28: 待执行
A29: 28 | B29: http-error-example | C29: httpPage | D29: pre | G29: { "code": "CONFLICT", "message": "库存不足", "data": null, "trace_id": "..." } | H29: [data-testid="http-error-example"] | I29: w_get_text | J29: 否 | K29: 否 | L29: =IF(COUNTIF('操作方法覆盖'!$G$2:$G$104,B29)>0,"已覆盖","未直接覆盖") | M29: 只读/状态元素：定位、读取文本或作为结果验证元素 | N29: 待执行
A30: 29 | B30: bootstrap-form | C30: httpPage | D30: form | G30: 任务名称 随机种子 登录账号 普通员工 部门经理 财务经理 总经理 管理员 密码 创建运行并登录 切换账号 清理运行 | H30: [data-testid="bootstrap-form"] | I30: w_get_text | J30: 否 | K30: 否 | L30: =IF(COUNTIF('操作方法覆盖'!$G$2:$G$104,B30)>0,"已覆盖","未直接覆盖") | M30: 只读/状态元素：定位、读取文本或作为结果验证元素 | N30: 待执行
A31: 30 | B31: run-name | C31: httpPage | D31: input | H31: [data-testid="run-name"] | I31: w_input | J31: 是 | K31: 否 | L31: =IF(COUNTIF('操作方法覆盖'!$G$2:$G$104,B31)>0,"已覆盖","未直接覆盖") | M31: 进入交互元素逐一操作 | N31: 待执行
A32: 31 | B32: run-seed | C32: httpPage | D32: input | E32: number | H32: [data-testid="run-seed"] | I32: w_input | J32: 是 | K32: 否 | L32: =IF(COUNTIF('操作方法覆盖'!$G$2:$G$104,B32)>0,"已覆盖","未直接覆盖") | M32: 进入交互元素逐一操作 | N32: 待执行
A33: 32 | B33: login-username | C33: httpPage | D33: select | G33: 普通员工 部门经理 财务经理 总经理 管理员 | H33: [data-testid="login-username"] | I33: w_select_option | J33: 是 | K33: 否 | L33: =IF(COUNTIF('操作方法覆盖'!$G$2:$G$104,B33)>0,"已覆盖","未直接覆盖") | M33: 进入交互元素逐一操作 | N33: 待执行
A34: 33 | B34: login-password | C34: httpPage | D34: input | E34: password | H34: [data-testid="login-password"] | I34: w_input | J34: 是 | K34: 否 | L34: =IF(COUNTIF('操作方法覆盖'!$G$2:$G$104,B34)>0,"已覆盖","未直接覆盖") | M34: 进入交互元素逐一操作 | N34: 待执行
A35: 34 | B35: create-run-login | C35: httpPage | D35: button | E35: submit | G35: 创建运行并登录 | H35: [data-testid="create-run-login"] | I35: w_click | J35: 是 | K35: 否 | L35: =IF(COUNTIF('操作方法覆盖'!$G$2:$G$104,B35)>0,"已覆盖","未直接覆盖") | M35: 进入交互元素逐一操作 | N35: 待执行
A36: 35 | B36: switch-login | C36: httpPage | D36: button | E36: button | G36: 切换账号 | H36: [data-testid="switch-login"] | I36: w_click | J36: 是 | K36: 否 | L36: =IF(COUNTIF('操作方法覆盖'!$G$2:$G$104,B36)>0,"已覆盖","未直接覆盖") | M36: 进入交互元素逐一操作 | N36: 待执行
A37: 36 | B37: cleanup-run | C37: httpPage | D37: button | E37: button | G37: 清理运行 | H37: [data-testid="cleanup-run"] | I37: w_click | J37: 是 | K37: 否 | L37: =IF(COUNTIF('操作方法覆盖'!$G$2:$G$104,B37)>0,"已覆盖","未直接覆盖") | M37: 进入交互元素逐一操作 | N37: 待执行
A38: 37 | B38: order-form | C38: httpPage | D38: form | G38: 商品 请先加载商品 数量 幂等键 加载商品 创建订单 支付 退款 | H38: [data-testid="order-form"] | I38: w_get_text | J38: 否 | K38: 否 | L38: =IF(COUNTIF('操作方法覆盖'!$G$2:$G$104,B38)>0,"已覆盖","未直接覆盖") | M38: 只读/状态元素：定位、读取文本或作为结果验证元素 | N38: 待执行
A39: 38 | B39: order-product | C39: httpPage | D39: select | G39: 请先加载商品 | H39: [data-testid="order-product"] | I39: w_select_option | J39: 是 | K39: 否 | L39: =IF(COUNTIF('操作方法覆盖'!$G$2:$G$104,B39)>0,"已覆盖","未直接覆盖") | M39: 进入交互元素逐一操作 | N39: 待执行
A40: 39 | B40: order-quantity | C40: httpPage | D40: input | E40: number | H40: [data-testid="order-quantity"] | I40: w_input | J40: 是 | K40: 否 | L40: =IF(COUNTIF('操作方法覆盖'!$G$2:$G$104,B40)>0,"已覆盖","未直接覆盖") | M40: 进入交互元素逐一操作 | N40: 待执行
A41: 40 | B41: order-idempotency-key | C41: httpPage | D41: input | H41: [data-testid="order-idempotency-key"] | I41: w_input | J41: 是 | K41: 否 | L41: =IF(COUNTIF('操作方法覆盖'!$G$2:$G$104,B41)>0,"已覆盖","未直接覆盖") | M41: 进入交互元素逐一操作 | N41: 待执行
A42: 41 | B42: load-products | C42: httpPage | D42: button | E42: button | G42: 加载商品 | H42: [data-testid="load-products"] | I42: w_click | J42: 是 | K42: 否 | L42: =IF(COUNTIF('操作方法覆盖'!$G$2:$G$104,B42)>0,"已覆盖","未直接覆盖") | M42: 进入交互元素逐一操作 | N42: 待执行
A43: 42 | B43: create-order | C43: httpPage | D43: button | E43: submit | G43: 创建订单 | H43: [data-testid="create-order"] | I43: w_click | J43: 是 | K43: 否 | L43: =IF(COUNTIF('操作方法覆盖'!$G$2:$G$104,B43)>0,"已覆盖","未直接覆盖") | M43: 进入交互元素逐一操作 | N43: 待执行
A44: 43 | B44: pay-order | C44: httpPage | D44: button | E44: button | G44: 支付 | H44: [data-testid="pay-order"] | I44: w_click | J44: 是 | K44: 否 | L44: =IF(COUNTIF('操作方法覆盖'!$G$2:$G$104,B44)>0,"已覆盖","未直接覆盖") | M44: 进入交互元素逐一操作 | N44: 待执行
...

Sheet 交互元素逐一操作
A1: 执行序号 | B1: 用例ID | C1: 所属页面 | D1: 元素ID | E1: 定位表达式 | F1: 控件类型 | G1: 执行方法 | H1: 参数(JSON) | I1: 前置导航/业务条件 | J1: 预期结果 | K1: 风险级别 | L1: 恢复/清理动作 | M1: 执行状态 | N1: 备注
A2: 1 | B2: UI-EL-001 | C2: global | D2: skip-to-content | E2: [data-testid="skip-to-content"] | F2: a | G2: w_click | H2: {} | I2: 打开首页 | J2: 链接可点击并打开正确地址；新页签用例执行后关闭页签 | K2: 低 | L2: 关闭新页签并切回首页 | M2: 待执行
A3: 2 | B3: UI-EL-002 | C3: global | D3: nav-scenarios | E3: [data-testid="nav-scenarios"] | F3: button | G3: w_click | H3: {} | I3: 打开首页 | J3: 控件可操作，页面状态、事件日志或目标业务结果发生预期变化 | K3: 低 | L3: 无需清理 | M3: 待执行
A4: 3 | B4: UI-EL-003 | C4: global | D4: nav-business | E4: [data-testid="nav-business"] | F4: button | G4: w_click | H4: {} | I4: 打开首页 | J4: 控件可操作，页面状态、事件日志或目标业务结果发生预期变化 | K4: 低 | L4: 无需清理 | M4: 待执行
A5: 4 | B5: UI-EL-004 | C5: global | D5: nav-sse | E5: [data-testid="nav-sse"] | F5: button | G5: w_click | H5: {} | I5: 打开首页 | J5: 控件可操作，页面状态、事件日志或目标业务结果发生预期变化 | K5: 低 | L5: 无需清理 | M5: 待执行
A6: 5 | B6: UI-EL-005 | C6: global | D6: nav-websocket | E6: [data-testid="nav-websocket"] | F6: button | G6: w_click | H6: {} | I6: 打开首页 | J6: 控件可操作，页面状态、事件日志或目标业务结果发生预期变化 | K6: 低 | L6: 无需清理 | M6: 待执行
A7: 6 | B7: UI-EL-006 | C7: global | D7: nav-mcp | E7: [data-testid="nav-mcp"] | F7: button | G7: w_click | H7: {} | I7: 打开首页 | J7: 控件可操作，页面状态、事件日志或目标业务结果发生预期变化 | K7: 低 | L7: 无需清理 | M7: 待执行
A8: 7 | B8: UI-EL-007 | C8: global | D8: nav-grpc | E8: [data-testid="nav-grpc"] | F8: button | G8: w_click | H8: {} | I8: 打开首页 | J8: 控件可操作，页面状态、事件日志或目标业务结果发生预期变化 | K8: 低 | L8: 无需清理 | M8: 待执行
A9: 8 | B9: UI-EL-008 | C9: global | D9: nav-components | E9: [data-testid="nav-components"] | F9: button | G9: w_click | H9: {} | I9: 打开首页 | J9: 控件可操作，页面状态、事件日志或目标业务结果发生预期变化 | K9: 低 | L9: 无需清理 | M9: 待执行
A10: 9 | B10: UI-EL-009 | C10: scenariosPage | D10: scenario-protocol | E10: [data-testid="scenario-protocol"] | F10: select | G10: w_select_option | H10: {"values":"http"} | I10: 点击 nav-scenarios | J10: 下拉框选中指定 value | K10: 低 | L10: 无需清理 | M10: 待执行
A11: 10 | B11: UI-EL-010 | C11: scenariosPage | D11: scenario-keyword | E11: [data-testid="scenario-keyword"] | F11: input | G11: w_input | H11: {"input_value":"AUTO_UI_CASE"} | I11: 点击 nav-scenarios | J11: 输入值与 Excel 参数一致，并触发 input/change 事件 | K11: 低 | L11: 无需清理 | M11: 待执行
A12: 11 | B12: UI-EL-011 | C12: scenariosPage | D12: refresh-scenarios | E12: [data-testid="refresh-scenarios"] | F12: button[button] | G12: w_click | H12: {} | I12: 点击 nav-scenarios | J12: 控件可操作，页面状态、事件日志或目标业务结果发生预期变化 | K12: 低 | L12: 无需清理 | M12: 待执行
A13: 12 | B13: UI-EL-012 | C13: httpPage | D13: open-swagger | E13: [data-testid="open-swagger"] | F13: a | G13: w_click | H13: {} | I13: 打开首页并切换到目标模块 | J13: 链接可点击并打开正确地址；新页签用例执行后关闭页签 | K13: 中 | L13: 关闭新页签并切回首页 | M13: 待执行
... A19: 18 | B19: UI-EL-018 | C19: httpPage | D19: switch-login | E19: [data-testid="switch-login"] | F19: button[button] | G19: w_click | H19: {} | I19: 打开首页并切换到目标模块 | J19: 控件可操作，页面状态、事件日志或目标业务结果发生预期变化 | K19: 低 | L19: 无需清理 | M19: 待执行
A20: 19 | B20: UI-EL-019 | C20: httpPage | D20: cleanup-run | E20: [data-testid="cleanup-run"] | F20: button[button] | G20: w_click | H20: {} | I20: 打开首页并切换到目标模块 | J20: 控件可操作，页面状态、事件日志或目标业务结果发生预期变化 | K20: 高 | L20: 必须最后执行；清理后不再执行依赖该运行的用例 | M20: 待执行 | N20: 调整执行顺序到全部业务用例之后
A21: 20 | B21: UI-EL-020 | C21: httpPage | D21: order-product | E21: [data-testid="order-product"] | F21: select | G21: w_select_option | H21: {"values":"请先加载商品"} | I21: 打开首页并切换到目标模块 | J21: 下拉框选中指定 value | K21: 低 | L21: 无需清理 | M21: 待执行
A22: 21 | B22: UI-EL-021 | C22: httpPage | D22: order-quantity | E22: [data-testid="order-quantity"] | F22: input[number] | G22: w_input | H22: {"input_value":2} | I22: 打开首页并切换到目标模块 | J22: 输入值与 Excel 参数一致，并触发 input/change 事件 | K22: 低 | L22: 无需清理 | M22: 待执行
A23: 22 | B23: UI-EL-022 | C23: httpPage | D23: order-idempotency-key | E23: [data-testid="order-idempotency-key"] | F23: input | G23: w_input | H23: {"input_value":"AUTO_UI_CASE"} | I23: 打开首页并切换到目标模块 | J23: 输入值与 Excel 参数一致，并触发 input/change 事件 | K23: 低 | L23: 无需清理 | M23: 待执行
A24: 23 | B24: UI-EL-023 | C24: httpPage | D24: load-products | E24: [data-testid="load-products"] | F24: button[button] | G24: w_click | H24: {} | I24: 打开首页并切换到目标模块 | J24: 控件可操作，页面状态、事件日志或目标业务结果发生预期变化 | K24: 低 | L24: 无需清理 | M24: 待执行
A25: 24 | B25: UI-EL-024 | C25: httpPage | D25: create-order | E25: [data-testid="create-order"] | F25: button[submit] | G25: w_click | H25: {} | I25: 打开首页并切换到目标模块 | J25: 控件可操作，页面状态、事件日志或目标业务结果发生预期变化 | K25: 低 | L25: 由 test_run 级清理统一回收业务数据 | M25: 待执行
A26: 25 | B26: UI-EL-025 | C26: httpPage | D26: pay-order | E26: [data-testid="pay-order"] | F26: button[button] | G26: w_click | H26: {} | I26: 打开首页并切换到目标模块 | J26: 控件可操作，页面状态、事件日志或目标业务结果发生预期变化 | K26: 高 | L26: 无需清理 | M26: 待执行
A27: 26 | B27: UI-EL-026 | C27: httpPage | D27: refund-order | E27: [data-testid="refund-order"] | F27: button[button] | G27: w_click | H27: {} | I27: 打开首页并切换到目标模块 | J27: 控件可操作，页面状态、事件日志或目标业务结果发生预期变化 | K27: 高 | L27: 无需清理 | M27: 待执行
A28: 27 | B28: UI-EL-027 | C28: httpPage | D28: claim-amount | E28: [data-testid="claim-amount"] | F28: input[number] | G28: w_input | H28: {"input_value":2} | I28: 打开首页并切换到目标模块 | J28: 输入值与 Excel 参数一致，并触发 input/change 事件 | K28: 低 | L28: 无需清理 | M28: 待执行
A29: 28 | B29: UI-EL-028 | C29: httpPage | D29: claim-reason | E29: [data-testid="claim-reason"] | F29: input | G29: w_input | H29: {"input_value":"AUTO_UI_CASE"} | I29: 打开首页并切换到目标模块 | J29: 输入值与 Excel 参数一致，并触发 input/change 事件 | K29: 低 | L29: 无需清理 | M29: 待执行
A30: 29 | B30: UI-EL-029 | C30: httpPage | D30: create-claim | E30: [data-testid="create-claim"] | F30: button[submit] | G30: w_click | H30: {} | I30: 打开首页并切换到目标模块 | J30: 控件可操作，页面状态、事件日志或目标业务结果发生预期变化 | K30: 低 | L30: 由 test_run 级清理统一回收业务数据 | M30: 待执行
A31: 30 | B31: UI-EL-030 | C31: httpPage | D31: query-claim | E31: [data-testid="query-claim"] | F31: button[button] | G31: w_click | H31: {} | I31: 打开首页并切换到目标模块 | J31: 控件可操作，页面状态、事件日志或目标业务结果发生预期变化 | K31: 低 | L31: 无需清理 | M31: 待执行
A32: 31 | B32: UI-EL-031 | C32: httpPage | D32: approve-claim | E32: [data-testid="approve-claim"] | F32: button[button] | G32: w_click | H32: {} | I32: 打开首页并切换到目标模块 | J32: 控件可操作，页面状态、事件日志或目标业务结果发生预期变化 | K32: 高 | L32: 无需清理 | M32: 待执行
... A131: 130 | B131: UI-EL-130 | C131: global | D131: confirm-modal | E131: [data-testid="confirm-modal"] | F131: button | G131: w_click | H131: {} | I131: 打开首页 | J131: 控件可操作，页面状态、事件日志或目标业务结果发生预期变化 | K131: 低 | L131: 无需清理 | M131: 待执行

Sheet 参数字典
A1: Excel UI 用例字段与参数字典
A3: 字段 | B3: 允许值/格式 | C3: 说明 | D3: 执行器解析规则 | E3: 示例 | F3: 注意事项
A4: 定位方式 | B4: TEST_ID | C4: 统一稳定定位 | D4: 转换为 page.get_by_test_id(element_id) 或 CSS locator | E4: single-click-target | F4: 禁止旧ID
A5: 定位表达式 | B5: [data-testid="..."] | C5: 可直接交给 Playwright | D5: 按 CSS 定位 | E5: [data-testid="single-click-target"] | F5: ID必须唯一
A6: 参数(JSON) | B6: JSON Object | C6: 只保存非 Locator 参数 | D6: locating 参数由元素ID自动注入 | E6: {"input_value":"AUTO"} | F6: 严格 JSON
A7: target_element_id | B7: 元素ID | C7: 双元素操作第二目标 | D7: 解析为 locating2 | E7: drop-target | F7: 用于 drag_to/新页签
A8: 缓存键 | B8: 字符串 | C8: 读取类方法保存结果 | D8: 写入 BaseData.test_data | E8: ui_read_text | F8: 同一用例内唯一
A9: test_run_id | B9: 运行时变量 | C9: 新版 Mock 隔离ID | D9: 执行前通过 API 创建并注入 Header | E9: ${test_run_id} | F9: 不可跨运行复用
A10: 执行状态 | B10: 待执行/执行中/通过/失败/阻塞/不适用 | C10: 测试结果 | D10: 由执行器回写 | E10: 待执行 | F10: 失败需截图
A11: 优先级 | B11: P0/P1/P2 | C11: P0为主链路 | D11: 用于筛选执行 | E11: P0 | F11: P0先运行
A12: 风险级别 | B12: 低/中/高 | C12: 页面副作用 | D12: 高风险串行并最后清理 | E12: 高 | F12: cleanup-run最后执行
A13: 输入数据前缀 | B13: AUTO_ | C13: 便于识别测试数据 | D13: Factory生成 | E13: AUTO_UI_CASE | F13: 不要写真实数据
A14: 截图路径 | B14: ${screenshot_dir}/name.png | C14: 由运行时替换目录 | D14: 传给 w_screenshot/w_ele_screenshot | E14: ${screenshot_dir}/page.png | F14: 目录需存在
... A17: 异常 | B17: MangoAutomationError | C17: 明确的自动化异常 | D17: 记录错误码、元素ID、方法和参数 | E17: MangoAutomationError | F17: 禁止吞异常
